Workbook

Sheet population
A1: Country | B1: Population | C1: airport count | D1: Airport/Population_Scaled | E1: Population/Airport
A2: Afghanistan | B2: 41454762 | C2: =VLOOKUP(population!A2,Airport_Count!$A$2:$B$219,2,FALSE) -> 4 | D2: =(C2*(10^6))/B2 -> 0.096490724 | E2: =B2/C2 -> 10363690
A3: Albania | B3: 2811660 | C3: =VLOOKUP(population!A3,Airport_Count!$A$2:$B$219,2,FALSE) -> 1 | D3: =(C3*(10^6))/B3 -> 0.35566178 | E3: =B3/C3 -> 2811660
A4: Algeria | B4: 46164222 | C4: =VLOOKUP(population!A4,Airport_Count!$A$2:$B$219,2,FALSE) -> 9 | D4: =(C4*(10^6))/B4 -> 0.19495617 | E4: =B4/C4 -> 5129358
A5: American Samoa | B5: 47544 | C5: =VLOOKUP(population!A5,Airport_Count!$A$2:$B$219,2,FALSE) -> #N/A | D5: =B5/C5 -> #N/A
A6: Andorra | B6: 80869 | C6: =VLOOKUP(population!A6,Airport_Count!$A$2:$B$219,2,FALSE) -> #N/A | D6: =B6/C6 -> #N/A
A7: Angola | B7: 36749909 | C7: =VLOOKUP(population!A7,Airport_Count!$A$2:$B$219,2,FALSE) -> 1 | D7: =(C7*(10^6))/B7 -> 0.027210952 | E7: =B7/C7 -> 36749909
A8: Anguilla | B8: 14435 | C8: =VLOOKUP(population!A8,Airport_Count!$A$2:$B$219,2,FALSE) -> 1 | D8: =(C8*(10^6))/B8 -> 69.276065 | E8: =B8/C8 -> 14435
A9: Antigua and Barbuda | B9: 93331 | C9: =VLOOKUP(population!A9,Airport_Count!$A$2:$B$219,2,FALSE) -> 1 | D9: =(C9*(10^6))/B9 -> 10.714554 | E9: =B9/C9 -> 93331
A10: Argentina | B10: 45538402 | C10: =VLOOKUP(population!A10,Airport_Count!$A$2:$B$219,2,FALSE) -> 4 | D10: =(C10*(10^6))/B10 -> 0.087837953 | E10: =B10/C10 -> 11384600
A11: Armenia | B11: 2943398 | C11: =VLOOKUP(population!A11,Airport_Count!$A$2:$B$219,2,FALSE) -> 1 | D11: =(C11*(10^6))/B11 -> 0.33974339 | E11: =B11/C11 -> 2943398
A12: Aruba | B12: 107946 | C12: =VLOOKUP(population!A12,Airport_Count!$A$2:$B$219,2,FALSE) -> 1 | D12: =(C12*(10^6))/B12 -> 9.2638912 | E12: =B12/C12 -> 107946
A13: Australia | B13: 26451126 | C13: =VLOOKUP(population!A13,Airport_Count!$A$2:$B$219,2,FALSE) -> 8 | D13: =(C13*(10^6))/B13 -> 0.30244459 | E13: =B13/C13 -> 3306390.8
A14: Austria | B14: 9130434 | C14: =VLOOKUP(population!A14,Airport_Count!$A$2:$B$219,2,FALSE) -> 6 | D14: =(C14*(10^6))/B14 -> 0.65714291 | E14: =B14/C14 -> 1521739
A15: Azerbaijan | B15: 10318209 | C15: =VLOOKUP(population!A15,Airport_Count!$A$2:$B$219,2,FALSE) -> 3 | D15: =(C15*(10^6))/B15 -> 0.29074813 | E15: =B15/C15 -> 3439403
A16: Bahamas | B16: 399452 | C16: =VLOOKUP(population!A16,Airport_Count!$A$2:$B$219,2,FALSE) -> 9 | D16: =(C16*(10^6))/B16 -> 22.530867 | E16: =B16/C16 -> 44383.556
A17: Bahrain | B17: 1569674 | C17: =VLOOKUP(population!A17,Airport_Count!$A$2:$B$219,2,FALSE) -> 1 | D17: =(C17*(10^6))/B17 -> 0.63707496 | E17: =B17/C17 -> 1569674
A18: Bangladesh | B18: 171466986 | C18: =VLOOKUP(population!A18,Airport_Count!$A$2:$B$219,2,FALSE) -> 3 | D18: =(C18*(10^6))/B18 -> 0.017496079 | E18: =B18/C18 -> 57155662
... A26: Bolivia | B26: 12244161 | C26: =VLOOKUP(population!A26,Airport_Count!$A$2:$B$219,2,FALSE) -> 2 | D26: =(C26*(10^6))/B26 -> 0.16334316 | E26: =B26/C26 -> 6122080.5
A27: Bonaire Sint Eustatius and Saba | B27: 29920 | C27: =VLOOKUP(population!A27,Airport_Count!$A$2:$B$219,2,FALSE) -> #N/A | D27: =B27/C27 -> #N/A
A28: Bosnia and Herzegovina | B28: 3185072 | C28: =VLOOKUP(population!A28,Airport_Count!$A$2:$B$219,2,FALSE) -> 3 | D28: =(C28*(10^6))/B28 -> 0.94189394 | E28: =B28/C28 -> 1061690.7
A29: Botswana | B29: 2480242 | C29: =VLOOKUP(population!A29,Airport_Count!$A$2:$B$219,2,FALSE) -> 3 | D29: =(C29*(10^6))/B29 -> 1.2095594 | E29: =B29/C29 -> 826747.33
A30: Brazil | B30: 211140731 | C30: =VLOOKUP(population!A30,Airport_Count!$A$2:$B$219,2,FALSE) -> 13 | D30: =(C30*(10^6))/B30 -> 0.061570309 | E30: =B30/C30 -> 16241595
A31: British Virgin Islands | B31: 39009 | C31: =VLOOKUP(population!A31,Airport_Count!$A$2:$B$219,2,FALSE) -> 2 | D31: =(C31*(10^6))/B31 -> 51.27022 | E31: =B31/C31 -> 19504.5
A32: Brunei | B32: 458959 | C32: =VLOOKUP(population!A32,Airport_Count!$A$2:$B$219,2,FALSE) -> 1 | D32: =(C32*(10^6))/B32 -> 2.1788439 | E32: =B32/C32 -> 458959
A33: Bulgaria | B33: 6795805 | C33: =VLOOKUP(population!A33,Airport_Count!$A$2:$B$219,2,FALSE) -> 4 | D33: =(C33*(10^6))/B33 -> 0.58859841 | E33: =B33/C33 -> 1698951.2
A34: Burkina Faso | B34: 23025777 | C34: =VLOOKUP(population!A34,Airport_Count!$A$2:$B$219,2,FALSE) -> 1 | D34: =(C34*(10^6))/B34 -> 0.043429588 | E34: =B34/C34 -> 23025777
A35: Burundi | B35: 13689455 | C35: =VLOOKUP(population!A35,Airport_Count!$A$2:$B$219,2,FALSE) -> 1 | D35: =(C35*(10^6))/B35 -> 0.073048927 | E35: =B35/C35 -> 13689455
A36: Cambodia | B36: 17423884 | C36: =VLOOKUP(population!A36,Airport_Count!$A$2:$B$219,2,FALSE) -> 2 | D36: =(C36*(10^6))/B36 -> 0.11478497 | E36: =B36/C36 -> 8711942
A37: Cameroon | B37: 28372690 | C37: =VLOOKUP(population!A37,Airport_Count!$A$2:$B$219,2,FALSE) -> 2 | D37: =(C37*(10^6))/B37 -> 0.07049032 | E37: =B37/C37 -> 14186345
A38: Canada | B38: 39299098 | C38: =VLOOKUP(population!A38,Airport_Count!$A$2:$B$219,2,FALSE) -> 19 | D38: =(C38*(10^6))/B38 -> 0.48347166 | E38: =B38/C38 -> 2068373.6
A39: Cape Verde | B39: 522335 | C39: =VLOOKUP(population!A39,Airport_Count!$A$2:$B$219,2,FALSE) -> 4 | D39: =(C39*(10^6))/B39 -> 7.6579207 | E39: =B39/C39 -> 130583.75
... A46: Comoros | B46: 850390 | C46: =VLOOKUP(population!A46,Airport_Count!$A$2:$B$219,2,FALSE) -> 1 | D46: =(C46*(10^6))/B46 -> 1.175931 | E46: =B46/C46 -> 850390
A47: Congo | B47: 6182890 | C47: =VLOOKUP(population!A47,Airport_Count!$A$2:$B$219,2,FALSE) -> #N/A | D47: =B47/C47 -> #N/A
A48: Cook Islands | B48: 14244 | C48: =VLOOKUP(population!A48,Airport_Count!$A$2:$B$219,2,FALSE) -> 1 | D48: =(C48*(10^6))/B48 -> 70.204999 | E48: =B48/C48 -> 14244
A49: Costa Rica | B49: 5105526 | C49: =VLOOKUP(population!A49,Airport_Count!$A$2:$B$219,2,FALSE) -> 2 | D49: =(C49*(10^6))/B49 -> 0.39173241 | E49: =B49/C49 -> 2552763
A50: Cote d'Ivoire | B50: 31165653 | C50: =VLOOKUP(population!A50,Airport_Count!$A$2:$B$219,2,FALSE) -> 1 | D50: =(C50*(10^6))/B50 -> 0.032086605 | E50: =B50/C50 -> 31165653
A51: Croatia | B51: 3896023 | C51: =VLOOKUP(population!A51,Airport_Count!$A$2:$B$219,2,FALSE) -> 6 | D51: =(C51*(10^6))/B51 -> 1.540032 | E51: =B51/C51 -> 649337.17
A52: Cuba | B52: 11019932 | C52: =VLOOKUP(population!A52,Airport_Count!$A$2:$B$219,2,FALSE) -> 7 | D52: =(C52*(10^6))/B52 -> 0.63521263 | E52: =B52/C52 -> 1574276
A53: Curacao | B53: 185437 | C53: =VLOOKUP(population!A53,Airport_Count!$A$2:$B$219,2,FALSE) -> #N/A | D53: =B53/C53 -> #N/A
...

Sheet Airport_Count
A1: Country | B1: Airport_Count
A2: Afghanistan | B2: 4
A3: Albania | B3: 1
A4: Algeria | B4: 9
A5: Angola | B5: 1
A6: Anguilla | B6: 1
A7: Antigua and Barbuda | B7: 1
A8: Argentina | B8: 4
A9: Armenia | B9: 1
A10: Aruba | B10: 1
A11: Australia | B11: 8
A12: Austria | B12: 6
A13: Azerbaijan | B13: 3
... A219: Zimbabwe | B219: 3

Sheet Number_of_Routes
A1: country | B1: num_countries_connected | C1: total_routes
A2: France | B2: 115 | C2: 873
A3: United Kingdom | B3: 99 | C3: 1282
A4: Germany | B4: 97 | C4: 1260
A5: United States | B5: 92 | C5: 1057
A6: United Arab Emirates | B6: 91 | C6: 384
A7: Turkey | B7: 90 | C7: 412
A8: Netherlands | B8: 81 | C8: 329
A9: Italy | B9: 77 | C9: 873
A10: Spain | B10: 73 | C10: 1055
A11: Russia | B11: 70 | C11: 566
A12: Canada | B12: 65 | C12: 324
A13: China | B13: 63 | C13: 580
... A219: Saint Pierre and Miquelon | B219: 1 | C219: 3

Sheet Geometry
A1: geometry | B1: Country name
A2: {"type":"MultiPolygon","coordinates":[[[[117.703608,4.163415],[117.838552,4.040188],[117.907039,4.156683],[117.703608,4.163415]]],[[[124.450531,-9.18019],[124.427939,-9.299483],[124.210692,-9.378858],[124.010102,-9.343927],[123.688813,-9.611423],[123.583751,-9.944024],[123.764659,-10.074965],[123.515391,-10.213067],[123.536469,-10.331964],[123.799327,-10.374688],[124.033865,-10.276137],[124.122406,-10.17254],[124.38087,-10.170505],[124.734548,-9.899509],[124.979747,-9.649021],[125.061615,-9.485772],[124.957933,-9.211943],[125.150634,-9.185381],[125.162365,-9.060634],[124.933025,-9.074484],[124.919507,-8.962016],[124.450531,-9.18019]]],[[[117.567149,4.159654],[117.43648,4.185611],[117.202696,4.356066],[116.804477,4.330073],[116.711666,4.366789],[116.411323,4.288654],[116.310657,4.383377],[116.125759,4.378907],[116.020649,4.270852],[115.844122,4.389216],[115.770742,4.225609],[115.646925,4.169101],[115.544399,3.629159],[115.601243,3.430231],[115.517631,3.357161],[115.464094,3.030824],[115.242092,3.041624],[115.069079,2.832645],[115.05647,2.608627],[115.206125,2.509874],[114.778761,2.247202],[114.831988,1.902521],[114.679542,1.840741],[114.669,1.694006],[114.545597,1.434952],[114.374858,1.506938],[114.173423,1.420509],[113.909667,1.442471],[113.624826,1.227575],[113.089045,1.431335],[112.973186,1.569854],[112.801517,1.543783],[112.470478,1.567657],[112.161556,1.434539],[112.09293,1.143135],[111.910099,1.114042],[111.823076,1.008467],[111.622675,1.030274],[111.503199,0.958444],[111.197584,1.075233],[110.880394,1.010534],[110.776731,0.903253],[110.553903,0.85137],[110.263481,0.994307],[110.17036,1.174451],[110.051814,1.215482],[109.65804,1.59719],[109.641814,1.781004],[109.528436,1.889989],[109.645274,2.083238],[109.578868,1.997626],[109.340994,1.935533],[109.272227,1.693793],[109.073009,1.533922],[109.054373,1.35224],[108.924327,1.164008],[108.980805,0.956041],[108.855479,0.832221],[108.931163,0.616197],[108.920909,0.340277],[109.102306,0.243109],[109.166759,0.112291],[109.190603,-0.188735],[109.100597,-0.369724],[109.139415,-0.528578],[109.26238,-0.592462],[109.273204,-0.853611],[109.427989,-0.846612],[109.740489,-0.967543],[110.061371,-1.346368],[110.033946,-1.646173],[109.903819,-1.826104],[110.09254,-1.94964],[110.097179,-2.235772],[110.221039,-2.53281],[110.263194,-3.002862],[110.54949,-2.867608],[110.630626,-3.053318],[110.754242,-3.026056],[110.986176,-3.087498],[111.363048,-2.922947],[111.569835,-3.01572],[111.703461,-2.943617],[111.83253,-3.061619],[111.842947,-3.384454],[111.905284,-3.572035],[112.202891,-3.329522],[112.348969,-3.322849],[112.545095,-3.444268],[112.638031,-3.416762],[113.021495,-3.16253],[113.201671,-3.093032],[113.351085,-3.272393],[113.611501,-3.174249],[113.632498,-3.456801],[113.814708,-3.455255],[114.042003,-3.355564],[114.26352,-3.397556],[114.522309,-3.519301],[114.611095,-3.683852],[114.664317,-4.184177],[115.060313,-3.985772],[115.583344,-3.780532],[115.858165,-3.620212],[115.967947,-3.608819],[116.023448,-3.411798],[116.167247,-3.156345],[116.161388,-3.003513],[116.287608,-2.987074],[116.364757,-2.861423],[116.393077,-2.573989],[116.517914,-2.553888],[116.603282,-2.224216],[116.37086,-2.137872],[116.457856,-2.042413],[116.424815,-1.766371],[116.540212,-1.622735],[116.567638,-1.446547],[116.957693,-1.239923],[117.250336,-0.909275],[117.446544,-0.877048],[117.55128,-0.68963],[117.630138,-0.418715],[117.435069,-0.239679],[117.530284,-0.032322],[117.469981,0.108791],[117.517263,0.290961],[117.743175,0.740546],[118.09669,0.908637],[118.565278,0.804023],[118.798188,0.804918],[119.011729,0.976264],[118.856944,1.058173],[118.754161,1.22956],[118.425059,1.485745],[118.12672,1.65469],[118.046153,1.783108],[117.85727,1.89765],[117.955414,2.182278],[118.082205,2.33747],[117.826182,2.607408],[117.736339,2.901597],[117.617198,3.085883],[117.352712,3.182807],[117.32545,3.436021],[117.199229,3.616278],[117.748546,3.636949],[117.826182,3.703599],[117.688487,3.909003],[117.520274,4.049302],[117.567149,4.159654]]],[[[140.974457,-2.600518],[140.698578,-2.608168],[140.74464,-2.499119],[140.15797,-2.320896],[139.780772,-2.354669],[139.1067,-2.012791],[138.842784,-1.94964],[138.665212,-1.789158],[138.07488,-1.610284],[137.839122,-1.471124],[137.123546,-1.797459],[137.204845,-1.94964],[137.178477,-2.106134],[136.981456,-2.12656],[136.749278,-2.252048],[136.532563,-2.189874],[136.38087,-2.234063],[136.266368,-2.560317],[135.96461,-2.775811],[135.909923,-2.985772],[135.757335,-3.055841],[135.505382,-3.348077],[135.340831,-3.389744],[135.002126,-3.336114],[134.898936,-3.262791],[134.772227,-2.977634],[134.701345,-2.958673],[134.638438,-2.511163],[134.484386,-2.539321],[134.532725,-2.834161],[134.463878,-2.862074],[134.330251,-2.522231],[134.19337,-2.379083],[134.120616,-2.135349],[134.155528,-2.039483],[134.087087,-1.682794],[134.215831,-1.560317],[134.281993,-1.350193],[134.036143,-0.957778],[134.17213,-0.863865],[133.977224,-0.72324],[133.572765,-0.750909],[133.391612,-0.72324],[133.154796,-0.531996],[132.709158,-0.36004],[132.396658,-0.353448],[132.15089,-0.435724],[131.876475,-0.68963],[131.516775,-0.785252],[131.243012,-0.819431],[131.236176,-1.117283],[131.03004,-1.275567],[130.977306,-1.452895],[131.57309,-1.480157],[131.804861,-1.607599],[132.04835,-2.083185],[132.305675,-2.265558],[132.560395,-2.185642],[132.688731,-2.307224],[133.296153,-2.204197],[133.645763,-2.236017],[133.858165,-2.107354],[133.963552,-2.32643],[133.819591,-2.477227],[133.518728,-2.589614],[133.445567,-2.494724],[133.239594,-2.416762],[133.033539,-2.479425],[132.853038,-2.717462],[132.728282,-2.813165],[132.585704,-2.717462],[132.311778,-2.676446],[132.044444,-2.803399],[132.101248,-2.959893],[132.325694,-2.946547],[132.553071,-3.107029],[132.671153,-3.328546],[132.931814,-3.554132],[132.730968,-3.682306],[132.907725,-4.088149],[133.250987,-4.066827],[133.45338,-3.865411],[133.408865,-3.722426],[133.641449,-3.483657],[133.838145,-3.590427],[133.971039,-3.850274],[134.192638,-3.835545],[134.191173,-3.943536],[134.430431,-3.90781],[134.525238,-4.026462],[134.675792,-3.90838],[134.733409,-4.197524],[134.906586,-4.264093],[135.185557,-4.448907],[135.429535,-4.430434],[135.95045,-4.50628],[136.035818,-4.586033],[136.375662,-4.68377],[136.822113,-4.928318],[136.946544,-4.917657],[137.369151,-5.026462],[137.690684,-5.211358],[137.914561,-5.386895],[138.054861,-5.589614],[138.071056,-5.728611],[138.262462,-5.914727],[138.365489,-6.091729],[138.466075,-6.402114],[138.829112,-6.705987],[138.739757,-6.897149],[138.561534,-6.918634],[138.761974,-7.113865],[138.667491,-7.197849],[138.865489,-7.336033],[138.944347,-7.497003],[139.093028,-7.559991],[139.007172,-7.754327],[138.993988,-7.865492],[138.915375,-7.903253],[138.925304,-8.070489],[138.842784,-8.117446],[138.914399,-8.292087],[139.089529,-8.133559],[139.395193,-8.200942],[139.630544,-8.124933],[139.973643,-8.096938],[139.988129,-8.192478],[140.363455,-8.490818],[140.856944,-9.049086],[140.97698,-9.106134],[140.977162,-6.896632],[140.8504,-6.623574],[140.950187,-6.498724],[140.976904,-6.335116],[140.974457,-2.600518]]],[[[109.906016,-7.83766],[110.476736,-8.111912],[111.161957,-8.281915],[111.276134,-8.248305],[111.630544,-8.3235],[111.792003,-8.256524],[111.970714,-8.277765],[112.672699,-8.447035],[113.026703,-8.302992],[113.240733,-8.280938],[113.413585,-8.390232],[113.979991,-8.620212],[114.302582,-8.611912],[114.366954,-8.741469],[114.555349,-8.777927],[114.358653,-8.409112],[114.467296,-7.830987],[114.045584,-7.611993],[113.785899,-7.726332],[113.528575,-7.700372],[113.32309,-7.785577],[112.761485,-7.531183],[112.823253,-7.262628],[112.614106,-7.091241],[112.542817,-6.917576],[112.435232,-6.870538],[112.083995,-6.90602],[111.976248,-6.784845],[111.740408,-6.781671],[111.493419,-6.623468],[111.366384,-6.712009],[111.144379,-6.691827],[111.010753,-6.420994],[110.842296,-6.418064],[110.671072,-6.499933],[110.644705,-6.688165],[110.486176,-6.937921],[110.381033,-6.975681],[110.212576,-6.899998],[109.940684,-6.923435],[109.531993,-6.835138],[109.351899,-6.875665],[108.944835,-6.849379],[108.605479,-6.761651],[108.539561,-6.486912],[108.186557,-6.231193],[108.093683,-6.326847],[107.895624,-6.231025],[107.678224,-6.238023],[107.470268,-6.145432],[107.354136,-5.975995],[107.169688,-5.97975],[107.005138,-6.072361],[106.793224,-6.104099],[106.685395,-6.012465],[106.470063,-6.034356],[106.298839,-5.945001],[106.15919,-6.009535],[106.052745,-5.881036],[105.867198,-6.110121],[105.824091,-6.434646],[105.440684,-6.794122],[105.535121,-6.872327],[105.978706,-6.817712],[106.333018,-7.000746],[106.540504,-7.054612],[106.386078,-7.230645],[106.522662,-7.410957],[107.411388,-7.495864],[107.864534,-7.74513],[108.453711,-7.818501],[108.539561,-7.692315],[109.098146,-7.686861],[109.368826,-7.713474],[109.42628,-7.774184],[109.906016,-7.83766]]],[[[119.846528,-0.874607],[119.68214,-0.736912],[119.525157,-0.860447],[119.453136,-1.096449],[119.31365,-1.245782],[119.305431,-1.652032],[119.347016,-1.959405],[119.216075,-2.009942],[119.134044,-2.203546],[119.135753,-2.454278],[118.914399,-2.64837],[118.806163,-2.629815],[118.771658,-2.862074],[118.885509,-2.869561],[118.817149,-3.171808],[118.926768,-3.566095],[119.297618,-3.427911],[119.497569,-3.495294],[119.454275,-3.700128],[119.593435,-4.026462],[119.626801,-4.314548],[119.591075,-4.564142],[119.497081,-4.71795],[119.519786,-4.916681],[119.403656,-5.124119],[119.352794,-5.355645],[119.569998,-5.655938],[119.805675,-5.692478],[119.914887,-5.568943],[120.100434,-5.595636],[120.323253,-5.509535],[120.387869,-5.352227],[120.264334,-5.149998],[120.309418,-4.87127],[120.449962,-4.64658],[120.367361,-4.424412],[120.359711,-3.89422],[120.446544,-3.728692],[120.398936,-3.500909],[120.425792,-3.256117],[120.203461,-2.957696],[120.799327,-2.615004],[121.00587,-2.660821],[121.080414,-2.759047],[121.066742,-3.19378],[120.889415,-3.388767],[120.874522,-3.498956],[121.354259,-3.968438],[121.627696,-4.087091],[121.48463,-4.656427],[121.704356,-4.835219],[122.077403,-4.842055],[122.039561,-4.663344],[122.107758,-4.519952],[122.599132,-4.396742],[122.758149,-4.484796],[122.900157,-4.388767],[122.907074,-4.195977],[122.711111,-4.11533],[122.441417,-3.731052],[122.205414,-3.593845],[122.25172,-3.376072],[122.385916,-3.132013],[122.312511,-2.926853],[122.015636,-2.693536],[122.009288,-2.59352],[121.822927,-2.287286],[121.574555,-2.16253],[121.43629,-1.980157],[121.692149,-1.908136],[121.861339,-1.669692],[122.368826,-1.492771],[122.720958,-1.109063],[122.838715,-0.899184],[123.149913,-0.935479],[123.383311,-1.003676],[123.454356,-0.758233],[123.403494,-0.642673],[123.239513,-0.570489],[122.823009,-0.612237],[122.716482,-0.792413],[122.622325,-0.750584],[122.207693,-0.764744],[122.105317,-0.926202],[121.714203,-0.935479],[121.659679,-0.812595],[121.500662,-0.859308],[121.206554,-1.191339],[121.105479,-1.405857],[120.675955,-1.394708],[120.56544,-1.215509],[120.586762,-1.116632],[120.412446,-0.904962],[120.255626,-0.899347],[120.07309,-0.613946],[119.995616,-0.209242],[120.158214,0.227769],[120.375255,0.477688],[120.679535,0.530585],[120.876475,0.424506],[121.107921,0.407131],[121.26059,0.482489],[121.495128,0.482815],[121.601899,0.551744],[121.800466,0.426459],[122.037771,0.482123],[122.565929,0.496527],[122.977875,0.482815],[123.074229,0.516303],[123.23878,0.32453],[123.571056,0.303616],[124.068533,0.351874],[124.465831,0.448676],[124.663829,0.805609],[124.898692,0.973049],[125.115408,1.385199],[125.249197,1.484687],[125.175304,1.678168],[124.968598,1.673814],[124.825938,1.572903],[124.835704,1.469143],[124.54835,1.359849],[124.54835,1.215806],[124.389415,1.186103],[124.290375,1.01732],[123.92921,0.831529],[123.383311,0.927883],[122.968028,0.962592],[122.848888,0.81802],[122.645274,0.959174],[122.454112,1.020657],[122.235362,1.009833],[121.926117,1.0987],[121.546723,1.072455],[121.45045,1.167426],[121.080414,1.331936],[120.833507,1.32567],[120.801768,1.052639],[120.662283,0.968817],[120.568126,0.782131],[120.346446,0.855618],[120.045746,0.734361],[120.032237,0.516303],[119.911794,0.4737],[119.869477,0.287177],[119.888194,0.071275],[119.799978,-0.123793],[119.757823,-0.469903],[119.854015,-0.716404],[119.846528,-0.874607]]],[[[100.947276,1.825385],[100.812755,2.03974],[100.561046,2.156806],[100.434337,2.273342],[100.312185,2.562893],[100.121104,2.66356],[99.997895,2.79914],[99.979503,2.948472],[99.857921,3.011461],[99.750743,3.180487],[99.558116,3.244574],[99.433279,3.38288],[99.179761,3.546338],[98.796582,3.725443],[98.67662,3.914547],[98.263031,4.177314],[98.275564,4.42536],[98.007009,4.633857],[97.90919,4.889594],[97.664399,5.073432],[97.526215,5.242255],[97.226553,5.146221],[96.973399,5.273424],[96.650564,5.216254],[96.406586,5.217231],[96.088064,5.295478],[95.887543,5.512152],[95.611583,5.626654],[95.431895,5.65469],[95.197276,5.546373],[95.253591,5.411566],[95.198985,5.292873],[95.29127,5.191636],[95.42628,4.827338],[96.01002,4.225653],[96.197765,4.121283],[96.479503,3.778713],[96.760509,3.748684],[97.018565,3.522691],[97.171641,3.254828],[97.270763,3.214423],[97.40504,2.943345],[97.602712,2.866197],[97.658214,2.411566],[97.744395,2.281073],[97.955903,2.271715],[98.269216,2.038072],[98.535167,1.936469],[98.822602,1.630439],[98.753429,1.535631],[98.844574,1.345893],[98.981212,0.831732],[99.100271,0.601752],[99.13795,0.263088],[99.61085,0.098578],[99.747244,-0.02984],[99.823985,-0.313409],[100.034923,-0.48797],[100.301443,-0.816339],[100.366059,-1.150486],[100.569184,-1.330824],[100.65447,-1.617608],[100.857595,-1.89186],[100.833995,-2.159112],[101.104828,-2.587091],[101.326996,-2.73919],[101.611339,-3.224542],[102.222179,-3.642836],[102.312511,-3.991469],[102.701182,-4.27044],[102.920421,-4.492608],[103.172862,-4.617934],[103.385997,-4.804946],[103.891124,-5.104181],[103.901378,-5.21852],[104.297699,-5.643324],[104.541759,-5.841892],[104.688731,-5.807875],[104.533214,-5.559828],[104.681326,-5.506931],[104.790782,-5.60947],[105.163259,-5.786065],[105.279633,-5.444268],[105.586192,-5.790785],[105.782563,-5.828546],[105.8296,-5.654718],[105.867442,-4.82464],[105.906261,-4.469334],[105.812755,-4.238702],[105.952485,-3.833754],[105.819591,-3.67254],[105.900238,-3.407159],[106.073009,-3.255548],[106.028494,-2.982843],[105.809581,-2.899021],[105.778087,-2.690118],[105.618419,-2.594903],[105.62379,-2.401788],[105.246918,-2.342869],[105.11671,-2.380466],[104.883311,-2.284926],[104.814626,-2.008396],[104.685802,-2.044692],[104.564464,-1.85768],[104.462738,-1.5735],[104.449229,-1.316013],[104.377208,-1.031671],[104.212413,-1.073337],[103.955821,-0.976983],[103.794119,-1.009454],[103.650401,-0.942966],[103.345551,-0.695896],[103.417979,-0.517755],[103.414561,-0.216729],[103.671153,-0.017429],[103.801768,-0.007257],[103.743419,0.27733],[103.362153,0.536282],[103.083751,0.51557],[102.877126,0.726386],[102.532237,0.742377],[102.208507,1.024075],[102.118175,1.386542],[101.749197,1.661526],[101.427013,1.709296],[101.317149,2.024604],[101.067393,2.219794],[100.885916,2.298285],[100.799978,2.20893],[100.947276,1.825385]]],[[[120.792491,-9.96087],[120.669688,-9.885186],[120.478282,-9.641046],[120.271169,-9.642511],[120.229259,-9.492283],[120.094249,-9.461196],[119.958751,-9.29046],[119.79949,-9.383722],[119.168712,-9.385512],[118.935395,-9.553399],[119.096853,-9.717543],[119.634451,-9.769138],[119.697113,-9.852634],[119.967296,-9.983575],[120.15561,-10.220961],[120.391612,-10.263116],[120.72462,-10.196873],[120.839854,-10.051365],[120.792491,-9.96087]]],[[[123.348643,-8.268813],[123.156505,-8.243585],[123.019542,-8.391778],[123.289317,-8.404474],[123.348643,-8.268813]]],[[[116.633311,-8.275079],[116.393809,-8.201104],[116.286388,-8.236261],[116.027937,-8.445008],[116.072645,-8.577784],[116.019298,-8.908136],[116.167247,-8.878513],[116.446611,-8.92008],[116.681,-8.556329],[116.743175,-8.391778],[116.633311,-8.275079]]],[[[119.203624,-8.610935],[119.052257,-8.645685],[119.051117,-8.470473],[118.972504,-8.302016],[118.46339,-8.249444],[118.312266,-8.37127],[118.149669,-8.134454],[117.917817,-8.08587],[117.740977,-8.147882],[117.71225,-8.240899],[117.970225,-8.461358],[118.133556,-8.486749],[117.969005,-8.748142],[117.805186,-8.719985],[117.743826,-8.569268],[117.43393,-8.481134],[117.195079,-8.357599],[116.790091,-8.583704],[116.824474,-8.799005],[116.763031,-9.015558],[117.126801,-9.091241],[117.192406,-9.023727],[117.388868,-9.053739],[117.725108,-8.912042],[117.890473,-8.936782],[118.024181,-8.850518],[118.157725,-8.867852],[118.294932,-8.765232],[118.465017,-8.865004],[118.714041,-8.799981],[118.908051,-8.850518],[118.971853,-8.751153],[119.151622,-8.742364],[119.203624,-8.610935]]],[[[123.026378,-8.288751],[122.862559,-8.069757],[122.740408,-8.222426],[122.758149,-8.361017],[122.485118,-8.483982],[122.477387,-8.594985],[122.288422,-8.633884],[122.039561,-8.514744],[121.680431,-8.511326],[121.50172,-8.601821],[120.976085,-8.337498],[120.74464,-8.329767],[120.593923,-8.233494],[120.212901,-8.292739],[120.02475,-8.384942],[119.807791,-8.570001],[119.805675,-8.740655],[119.975759,-8.813897],[120.165294,-8.76865],[120.279063,-8.82936],[120.577891,-8.790216],[120.747813,-8.871026],[120.833181,-8.81699],[120.994884,-8.940525],[121.340587,-8.918064],[121.396007,-8.794122],[121.780447,-8.887953],[122.114513,-8.732354],[122.449474,-8.734308],[122.807384,-8.610935],[122.904145,-8.363377],[123.026378,-8.288751]]],[[[115.619151,-8.288751],[115.502452,-8.172621],[115.193126,-8.055108],[115.022634,-8.172621],[114.857595,-8.193129],[114.504731,-8.090427],[114.468435,-8.21852],[114.604503,-8.386489],[114.927013,-8.467462],[115.156098,-8.662042],[115.604828,-8.501072],[115.714203,-8.375177],[115.619151,-8.288751]]],[[[115.570649,-6.904555],[115.275727,-6.835382],[115.27589,-6.938735],[115.570649,-6.904555]]],[[[116.303722,-3.718032],[116.267833,-3.218845],[116.119395,-3.324151],[116.016368,-3.629164],[116.074474,-3.800877],[116.091482,-4.066827],[116.306488,-3.904474],[116.303722,-3.718032]]],[[[100.398611,-3.183526],[100.46754,-3.015313],[100.227306,-2.772638],[100.189464,-2.966567],[100.398611,-3.183526]]],[[[100.206798,-2.693536],[99.97462,-2.49391],[99.986827,-2.767185],[100.13852,-2.820489],[100.206798,-2.693536]]],[[[99.823253,-2.292901],[99.694347,-2.067804],[99.52768,-2.14544],[99.603526,-2.265558],[99.823253,-2.292901]]],[[[109.759776,-1.103936],[109.723481,-0.987074],[109.475434,-0.976983],[109.417247,-1.25449],[109.502452,-1.292169],[109.759776,-1.103936]]],[[[99.274425,-1.634942],[98.938324,-1.065118],[98.898204,-0.915704],[98.658214,-0.963474],[98.593761,-1.198419],[98.884776,-1.679376],[99.1185,-1.802341],[99.254893,-1.772068],[99.274425,-1.634942]]],[[[103.048676,0.797024],[102.763845,1.011176],[102.605479,1.011176],[102.406505,0.873236],[102.516368,0.791327],[103.048676,0.797024]]],[[[103.126475,0.927883],[103.03712,1.044582],[102.801768,1.163275],[102.790701,1.03148],[103.126475,0.927883]]],[[[104.146332,1.160468],[104.030935,1.187893],[103.906749,1.071682],[104.092296,0.989936],[104.146332,1.160468]]],[[[104.654552,1.096381],[104.399669,1.202623],[104.231944,1.093329],[104.271007,1.003607],[104.599864,0.835028],[104.654552,1.096381]]],[[[102.473399,1.242011],[102.290863,1.404527],[102.210623,1.398261],[102.232921,1.099514],[102.369314,0.935207],[102.468028,0.972561],[102.473399,1.242011]]],[[[102.49586,1.363593],[102.462657,1.515448],[102.072439,1.623236],[102.095551,1.475246],[102.49586,1.363593]]],[[[101.721202,2.058092],[101.649262,2.128485],[101.418142,2.04442],[101.397146,1.909369],[101.490733,1.736762],[101.715099,1.778225],[101.775564,1.947984],[101.721202,2.058092]]],[[[96.479503,2.414984],[96.424327,2.510565],[96.003266,2.777004],[95.791515,2.942532],[95.740082,2.778062],[95.790538,2.654608],[96.065684,2.579413],[96.285167,2.436428],[96.479503,2.414984]]],[[[108.396169,3.874823],[108.396169,3.990912],[108.224864,4.244818],[107.98463,4.01203],[108.062348,3.855943],[108.317638,3.683783],[108.396169,3.874823]]],[[[123.390147,-10.591485],[123.386485,-10.433038],[123.049164,-10.711358],[122.812511,-10.778416],[122.841807,-10.921075],[123.209158,-10.813084],[123.390147,-10.591485]]],[[[123.927989,-8.227309],[123.804454,-8.178888],[123.639171,-8.294122],[123.357595,-8.41131],[123.406749,-8.589451],[123.687511,-8.436212],[123.789887,-8.293634],[123.927989,-8.227309]]],[[[138.897309,-8.337172],[138.816905,-8.161879],[138.675059,-8.189142],[138.548025,-8.347101],[138.894054,-8.40545],[138.897309,-8.337172]]],[[[125.134044,-8.217055],[125.086925,-8.158787],[124.687999,-8.165216],[124.475271,-8.132582],[124.333507,-8.413018],[124.427908,-8.467462],[124.661632,-8.403416],[125.123302,-8.352309],[125.134044,-8.217055]]],[[[128.090587,-8.131036],[127.83253,-8.098565],[127.843598,-8.205743],[128.025645,-8.261407],[128.090587,-8.131036]]],[[[129.841156,-7.877862],[129.632498,-7.795994],[129.585216,-7.902032],[129.776378,-8.055352],[129.841156,-7.877862]]],[[[126.836762,-7.726332],[126.626964,-7.559991],[126.32838,-7.695733],[125.968923,-7.660089],[125.81422,-7.850274],[126.421886,-7.93255],[126.559337,-7.81992],[126.836762,-7.726332]]],[[[138.938975,-7.542087],[138.804535,-7.3742],[138.39503,-7.40488],[138.244151,-7.456476],[138.006684,-7.637628],[137.759044,-8.073419],[137.638194,-8.425877],[137.849132,-8.377537],[138.375987,-8.409601],[138.660899,-8.169041],[138.904145,-8.07586],[138.891124,-7.898045],[138.977224,-7.840916],[138.993663,-7.720147],[139.075531,-7.576267],[138.938975,-7.542087]]],[[[131.698578,-7.226739],[131.568614,-7.130955],[131.453136,-7.334405],[131.241547,-7.487726],[131.114757,-7.706964],[131.116222,-8.000746],[131.229666,-8.003513],[131.633067,-7.62005],[131.642751,-7.254815],[131.698578,-7.226739]]],[[[114.045665,-6.914646],[113.923676,-6.864841],[113.526228,-6.896293],[112.915294,-6.891697],[112.692638,-7.058526],[112.72641,-7.158787],[113.12794,-7.231052],[113.472471,-7.22205],[113.610052,-7.129187],[113.872813,-7.128839],[114.045665,-6.914646]]],[[[134.484386,-6.575616],[134.457042,-6.445245],[134.102712,-6.180108],[134.120372,-6.419854],[134.052989,-6.764337],[134.185069,-6.918634],[134.31072,-6.85947],[134.484386,-6.575616]]],[[[134.758067,-6.157892],[134.656993,-5.953871],[134.758067,-5.671319],[134.628266,-5.444757],[134.508311,-5.429376],[134.351817,-5.714451],[134.276622,-6.119317],[134.333507,-6.221449],[134.607758,-6.369561],[134.758067,-6.157892]]],[[[122.067393,-5.21502],[121.977306,-5.070489],[121.853852,-5.102146],[121.806814,-5.259861],[121.968272,-5.46795],[122.046886,-5.451593],[122.067393,-5.21502]]],[[[122.78004,-4.916599],[122.711111,-4.615492],[122.38266,-4.745864],[122.327485,-4.842055],[122.402599,-5.061782],[122.33253,-5.123793],[122.279633,-5.369724],[122.598399,-5.420099],[122.658539,-5.296482],[122.604259,-5.159926],[122.78004,-4.916599]]],[[[123.149913,-5.22503],[122.985362,-5.064874],[123.052094,-4.74033],[123.20045,-4.589044],[123.041352,-4.384373],[122.908946,-4.474542],[122.854991,-4.609552],[122.833507,-4.929132],[122.757579,-5.20672],[122.567149,-5.506931],[122.638357,-5.662205],[122.827647,-5.676202],[122.97755,-5.39422],[123.14503,-5.385431],[123.149913,-5.22503]]],[[[123.204438,-3.992934],[123.028168,-3.97381],[122.950694,-4.047052],[123.136241,-4.238702],[123.253429,-4.089776],[123.204438,-3.992934]]],[[[128.330821,-3.511895],[128.047699,-3.584731],[127.986013,-3.77158],[128.236501,-3.722263],[128.330821,-3.511895]]],[[[127.240896,-3.470961],[127.259776,-3.371189],[127.054535,-3.323012],[127.093516,-3.200779],[126.840017,-3.073663],[126.421397,-3.070489],[126.202001,-3.181842],[126.090921,-3.112098],[125.991742,-3.248191],[126.052628,-3.44632],[126.203021,-3.630994],[126.696573,-3.863792],[126.907,-3.787341],[127.243419,-3.606052],[127.240896,-3.470961]]],[[[130.87322,-3.573989],[130.81658,-3.434259],[130.666677,-3.403578],[130.587901,-3.12949],[130.389334,-2.993829],[129.964854,-2.973565],[129.541026,-2.780043],[129.400238,-2.791599],[129.177094,-2.957696],[129.052908,-2.804457],[128.865245,-2.862074],[128.51588,-2.834161],[128.175466,-2.857029],[128.008067,-3.073663],[127.842296,-3.173272],[127.981456,-3.385024],[128.090668,-3.132013],[128.272146,-3.211521],[128.484141,-3.462498],[128.877452,-3.202569],[129.084321,-3.341241],[129.485606,-3.463474],[129.509613,-3.302504],[129.890473,-3.333103],[130.00172,-3.473077],[130.418793,-3.636895],[130.616466,-3.78631],[130.841563,-3.865004],[130.87322,-3.573989]]],[[[108.293712,-2.848403],[108.097911,-2.608168],[107.670258,-2.561456],[107.594249,-2.78631],[107.581065,-3.010675],[107.642589,-3.128351],[107.980968,-3.239841],[108.183849,-3.10475],[108.293712,-2.848403]]],[[[126.329112,-1.819268],[125.946137,-1.785821],[125.702891,-1.819268],[125.40211,-1.774672],[125.43214,-1.94964],[125.871755,-1.90252],[125.927582,-1.93141],[126.272146,-1.867283],[126.329112,-1.819268]]],[[[130.386485,-1.888279],[130.351817,-1.741388],[130.030772,-1.743829],[129.714854,-1.881443],[129.873383,-1.982029],[130.256114,-2.045831],[130.386485,-1.888279]]],[[[125.314789,-1.778985],[125.120291,-1.682794],[124.955577,-1.696466],[124.632823,-1.631117],[124.384939,-1.667901],[124.329112,-1.870782],[124.406016,-2.004083],[124.543224,-2.006524],[124.828298,-1.895115],[125.31837,-1.882582],[125.314789,-1.778985]]],[[[136.848481,-1.765313],[136.368175,-1.724298],[136.191254,-1.653904],[135.896739,-1.648045],[135.477306,-1.589939],[135.497895,-1.682794],[135.718028,-1.703302],[136.266368,-1.909356],[136.536306,-1.901788],[136.848481,-1.765313]]],[[[106.769054,-2.560317],[106.396169,-2.48211],[106.318858,-2.431329],[106.200694,-2.178155],[106.179454,-1.888279],[105.913748,-1.494236],[105.459646,-1.562921],[105.349864,-1.648696],[105.402354,-1.783298],[105.135916,-1.965509],[105.147472,-2.080011],[105.306407,-2.135024],[105.607432,-2.114841],[105.780447,-2.150811],[105.828787,-2.395115],[105.944347,-2.498793],[105.907563,-2.674574],[105.986501,-2.821222],[106.436046,-2.970636],[106.532237,-3.105645],[106.751964,-3.073663],[106.60377,-2.910252],[106.769054,-2.560317]]],[[[128.145193,-1.594008],[127.898936,-1.42669],[127.634288,-1.328709],[127.487804,-1.449965],[127.378673,-1.632257],[127.532725,-1.731378],[127.913097,-1.682387],[128.051524,-1.714532],[128.145193,-1.594008]]],[[[123.503103,-1.264418],[123.352224,-1.229181],[123.231944,-1.394708],[123.146251,-1.183201],[122.913829,-1.176365],[122.812022,-1.443617],[122.895844,-1.589532],[123.152354,-1.300551],[123.184825,-1.48561],[123.288585,-1.421563],[123.408376,-1.516534],[123.528575,-1.433038],[123.503103,-1.264418]]],[[[131.057384,-1.000665],[130.891856,-0.889907],[130.64975,-0.97381],[130.758067,-1.238214],[130.961925,-1.353774],[131.037364,-1.226332],[131.057384,-1.000665]]],[[[130.917247,-0.778416],[130.817882,-0.819431],[130.478526,-0.7999],[130.400157,-0.929295],[130.819347,-0.870294],[130.917247,-0.778416]]],[[[136.375662,-1.093683],[136.1963,-1.066583],[136.065766,-0.871677],[135.869314,-0.70379],[135.370372,-0.635919],[135.393728,-0.723403],[135.660818,-0.88714],[135.765391,-0.839288],[135.834321,-1.128513],[136.160655,-1.22088],[136.375662,-1.093683]]],[[[104.548513,-0.398045],[104.339366,-0.346449],[104.25587,-0.475518],[104.511241,-0.613946],[104.548513,-0.398045]]],[[[127.888927,-0.764744],[127.604015,-0.61712],[127.687999,-0.480645],[127.578624,-0.324965],[127.295258,-0.494317],[127.398611,-0.620212],[127.457693,-0.815606],[127.625743,-0.752374],[127.754893,-0.887628],[127.888927,-0.764744]]],[[[131.297618,-0.237237],[131.153656,-0.085707],[130.824718,-0.003839],[130.28061,-0.104994],[130.523692,-0.257582],[130.688243,-0.291192],[130.756033,-0.445977],[131.098481,-0.322931],[131.25294,-0.384373],[131.297618,-0.237237]]],[[[104.928966,-0.237237],[104.766287,-0.188246],[104.564626,0.030341],[104.435557,-0.192153],[104.541352,-0.271254],[104.735525,-0.214451],[104.928966,-0.237237]]],[[[97.928477,0.99608],[97.693614,1.186021],[97.486339,1.476549],[97.33546,1.537665],[97.23585,1.416693],[97.247244,1.267035],[97.371593,1.05976],[97.61378,0.823554],[97.704112,0.57274],[97.874278,0.622016],[97.928477,0.99608]]],[[[127.666026,-0.209242],[127.88559,-0.40602],[128.032237,-0.699314],[128.227794,-0.709568],[128.096365,-0.517267],[127.885753,0.023505],[127.878266,0.32453],[127.960216,0.482815],[128.262218,0.391343],[128.690115,0.346991],[128.680837,0.554511],[128.364594,0.643622],[128.213552,0.773912],[128.300466,0.893744],[128.701182,1.070868],[128.740977,1.404853],[128.719493,1.570624],[128.437266,1.539293],[128.2046,1.38996],[127.993907,1.082994],[127.923025,0.869818],[127.741873,0.81802],[127.637543,1.000718],[127.890636,1.152411],[128.03533,1.537991],[128.014903,1.719224],[127.846446,1.851467],[128.029063,2.109687],[127.934825,2.187649],[127.629731,1.835395],[127.555675,1.692532],[127.540782,1.475653],[127.398611,1.209052],[127.491954,1.054918],[127.555431,0.739895],[127.526866,0.560614],[127.576508,0.415513],[127.715587,0.312567],[127.666026,-0.209242]]],[[[128.686371,2.483954],[128.566417,2.633612],[128.321137,2.458645],[128.197113,2.266181],[128.288585,2.039618],[128.490245,2.054267],[128.6421,2.261176],[128.686371,2.483954]]],[[[126.870709,4.331393],[126.875011,4.49433],[126.744395,4.5456],[126.676286,4.060346],[126.798438,4.017644],[126.870709,4.331393]]]]} | B2: Indonesia
A3: {"type":"MultiPolygon","coordinates":[[[[102.07309,6.257514],[102.060002,6.094797],[101.934739,5.981729],[101.800483,5.739909],[101.557914,5.911346],[101.248993,5.786986],[101.122179,5.62989],[100.965289,5.792412],[101.07877,5.938166],[101.081664,6.246467],[100.832997,6.236675],[100.805609,6.414803],[100.329204,6.557766],[100.166836,6.695122],[100.137462,6.38052],[100.349132,6.012681],[100.350841,5.584215],[100.433279,5.211168],[100.364513,5.084296],[100.44158,4.922838],[100.617361,4.792914],[100.645518,4.560045],[100.56544,4.319159],[100.76588,4.09984],[100.709483,3.883043],[101.040538,3.621975],[101.108409,3.473944],[101.297618,3.274604],[101.372813,3.002346],[101.283051,2.9112],[101.542328,2.661282],[101.774425,2.586575],[101.851085,2.478949],[102.154307,2.235663],[102.544688,2.057685],[102.699392,1.859442],[103.367361,1.538398],[103.454845,1.339423],[103.600108,1.353461],[103.697602,1.450629],[103.839692,1.476549],[104.106212,1.37519],[104.293712,1.471584],[104.195323,1.798733],[103.97641,2.192369],[103.948985,2.339911],[103.765147,2.648912],[103.638438,2.672105],[103.441173,2.922105],[103.428071,3.367174],[103.482188,3.511786],[103.338715,3.758205],[103.434337,3.950019],[103.395193,4.116278],[103.49643,4.30622],[103.451427,4.488471],[103.448009,4.806545],[103.222423,5.221137],[103.027599,5.4855],[102.6692,5.725002],[102.520763,5.871731],[102.338145,6.176988],[102.07309,6.257514]]],[[[115.146169,4.908515],[115.272684,4.636772],[115.272478,4.474663],[115.091817,4.405417],[115.026808,4.660027],[114.948363,4.818932],[114.741967,4.729454],[114.84563,4.395108],[114.766875,4.131816],[114.627762,4.016681],[114.41992,4.260129],[114.282667,4.264909],[114.245564,4.481433],[113.975841,4.594713],[113.946788,4.27383],[113.736827,4.001288],[113.434255,3.75316],[113.277599,3.484198],[113.007823,3.161689],[112.01352,2.885932],[111.669607,2.843085],[111.457856,2.705634],[111.365489,2.340766],[111.246349,2.436103],[111.184825,2.253648],[111.205903,2.068996],[111.005626,1.584459],[110.726736,1.547431],[110.290782,1.673977],[109.927745,1.692288],[109.693044,1.873114],[109.645274,2.083238],[109.528436,1.889989],[109.641814,1.781004],[109.65804,1.59719],[110.051814,1.215482],[110.17036,1.174451],[110.263481,0.994307],[110.553903,0.85137],[110.776731,0.903253],[110.880394,1.010534],[111.197584,1.075233],[111.503199,0.958444],[111.622675,1.030274],[111.823076,1.008467],[111.910099,1.114042],[112.09293,1.143135],[112.161556,1.434539],[112.470478,1.567657],[112.801517,1.543783],[112.973186,1.569854],[113.089045,1.431335],[113.624826,1.227575],[113.909667,1.442471],[114.173423,1.420509],[114.374858,1.506938],[114.545597,1.434952],[114.669,1.694006],[114.679542,1.840741],[114.831988,1.902521],[114.778761,2.247202],[115.206125,2.509874],[115.05647,2.608627],[115.069079,2.832645],[115.242092,3.041624],[115.464094,3.030824],[115.517631,3.357161],[115.601243,3.430231],[115.544399,3.629159],[115.646925,4.169101],[115.770742,4.225609],[115.844122,4.389216],[116.020649,4.270852],[116.125759,4.378907],[116.310657,4.383377],[116.411323,4.288654],[116.711666,4.366789],[116.804477,4.330073],[117.202696,4.356066],[117.43648,4.185611],[117.567149,4.159654],[117.656016,4.424221],[117.982677,4.231147],[118.353282,4.361518],[118.556895,4.363511],[118.496593,4.508287],[118.277599,4.695136],[118.136485,4.88231],[118.357188,5.038804],[118.49936,4.931464],[118.681488,4.944322],[119.155935,5.106187],[119.2671,5.201077],[119.278087,5.344631],[118.819347,5.478095],[118.594005,5.682074],[118.365245,5.813788],[118.17628,5.805162],[118.134044,5.689643],[117.960297,5.687161],[117.921153,5.809027],[118.125173,5.863918],[118.016856,6.060981],[117.774262,5.908026],[117.668956,5.972642],[117.600352,6.197821],[117.722992,6.254625],[117.727061,6.451158],[117.295909,6.636298],[117.150238,7.003119],[116.973806,6.708075],[116.858653,6.817857],[116.777354,7.02676],[116.6692,6.87641],[116.639008,6.699286],[116.503184,6.495185],[116.105968,6.126451],[116.050792,5.842271],[115.930675,5.763007],[115.848643,5.560004],[115.619151,5.568061],[115.392589,5.413275],[115.556977,5.067206],[115.358409,4.902777],[115.146169,4.908515]]],[[[100.309825,5.450751],[100.179454,5.458197],[100.184337,5.268541],[100.288748,5.262681],[100.309825,5.450751]]]]} | B3: Malaysia
A4: {"type":"MultiPolygon","coordinates":[[[[-69.510089,-17.506588],[-69.683902,-17.656036],[-69.849835,-17.69159],[-69.783095,-17.981598],[-69.970345,-18.250625],[-70.159067,-18.32597],[-70.394703,-18.337746],[-70.329335,-18.471856],[-70.356597,-18.77337],[-70.266225,-19.178399],[-70.28775,-19.300958],[-70.199574,-19.534356],[-70.12328,-20.072198],[-70.2058,-20.52809],[-70.171295,-21.014581],[-70.080094,-21.233325],[-70.058695,-21.433377],[-70.150217,-21.653497],[-70.150054,-21.861993],[-70.248199,-22.327569],[-70.24059,-22.487563],[-70.312571,-22.790623],[-70.291575,-22.901951],[-70.425423,-23.08853],[-70.562245,-23.059828],[-70.585072,-23.423598],[-70.390736,-23.576918],[-70.498525,-23.784601],[-70.506098,-24.167381],[-70.582834,-24.524835],[-70.576405,-24.731703],[-70.472727,-24.975274],[-70.444814,-25.344903],[-70.646881,-25.521661],[-70.710357,-25.835382],[-70.635976,-25.974705],[-70.695302,-26.568536],[-70.822418,-26.865818],[-70.788645,-26.99627],[-70.95995,-27.161391],[-70.912424,-27.62184],[-71.038686,-27.666436],[-71.173085,-28.09295],[-71.188588,-28.40545],[-71.316233,-28.572931],[-71.301869,-28.6749],[-71.521962,-28.940118],[-71.486928,-29.211847],[-71.360911,-29.295587],[-71.288075,-29.603123],[-71.282582,-29.880141],[-71.506093,-30.271905],[-71.637766,-30.241469],[-71.71345,-30.614923],[-71.654937,-30.976007],[-71.666168,-31.169854],[-71.514963,-31.775486],[-71.542144,-32.205173],[-71.407948,-32.386326],[-71.454172,-32.685642],[-71.548695,-32.784845],[-71.568227,-33.001886],[-71.761871,-33.101983],[-71.624664,-33.541436],[-71.671864,-33.6985],[-71.816518,-33.787286],[-72.018544,-34.140802],[-72.05724,-34.658787],[-72.187815,-34.885512],[-72.23058,-35.116143],[-72.398061,-35.233494],[-72.529652,-35.490411],[-72.646596,-35.566583],[-72.583567,-35.770603],[-72.80016,-35.978123],[-72.826161,-36.287042],[-72.981923,-36.690362],[-73.152821,-36.706964],[-73.209055,-37.160252],[-73.460683,-37.241957],[-73.607574,-37.15545],[-73.680409,-37.347833],[-73.599273,-37.447849],[-73.666575,-37.725518],[-73.462961,-38.051202],[-73.543284,-38.420668],[-73.245432,-39.221287],[-73.224477,-39.41725],[-73.406077,-39.69492],[-73.401926,-39.804132],[-73.711171,-39.968683],[-73.782826,-40.424574],[-73.728498,-40.54418],[-73.946904,-40.972841],[-73.759946,-41.748841],[-73.515045,-41.803643],[-73.201405,-41.784763],[-73.111887,-41.586196],[-72.957265,-41.483575],[-72.751576,-41.548435],[-72.645131,-41.722833],[-72.88858,-41.910821],[-72.488026,-42.127537],[-72.809722,-42.243259],[-72.678456,-42.478448],[-72.840321,-42.524835],[-72.842193,-42.838067],[-72.761057,-43.009047],[-72.934438,-43.09824],[-72.91218,-43.235447],[-73.084584,-43.316339],[-73.111318,-43.461033],[-72.973012,-43.621352],[-73.070424,-43.914483],[-73.290028,-44.152439],[-72.939931,-44.306736],[-72.67984,-44.543552],[-72.810048,-44.767755],[-73.117096,-44.948337],[-73.348256,-44.957778],[-73.304433,-45.144789],[-73.448069,-45.279474],[-73.660553,-45.975681],[-73.601308,-46.318455],[-73.873891,-46.602227],[-73.989166,-46.559747],[-73.769846,-46.234552],[-74.118642,-45.896254],[-74.170277,-45.791762],[-74.665598,-45.823337],[-74.737864,-46.023126],[-74.958119,-46.215265],[-75.090688,-46.216078],[-75.636057,-46.573012],[-75.707021,-46.786554],[-75.551747,-46.948337],[-75.410553,-46.931573],[-75.422475,-46.713962],[-75.111643,-46.586847],[-75.0065,-46.753513],[-74.680979,-46.883884],[-74.640004,-46.780043],[-74.289906,-46.82171],[-74.153228,-46.967218],[-73.941274,-47.027927],[-74.115387,-47.192966],[-74.324696,-47.218927],[-74.556711,-47.550063],[-74.735585,-47.718683],[-74.548899,-47.784763],[-74.067738,-47.770766],[-73.55012,-47.808038],[-73.642201,-47.983575],[-74.060618,-48.000421],[-74.537465,-47.963067],[-74.625409,-48.004227],[-74.27009,-48.335626],[-74.029897,-48.41131],[-74.392161,-48.599054],[-74.468658,-49.031671],[-74.371897,-49.186619],[-74.42276,-49.384698],[-74.241119,-49.527927],[-74.346669,-50.015232],[-74.694651,-50.183038],[-74.297353,-50.480645],[-74.126088,-50.762465],[-74.225209,-50.955824],[-74.129506,-51.187677],[-73.879384,-51.237888],[-73.899526,-51.625177],[-73.645579,-51.848728],[-73.563547,-52.039972],[-73.316233,-52.166111],[-73.145334,-51.940037],[-72.578033,-51.795994],[-72.468984,-51.929295],[-72.864858,-51.954767],[-73.303049,-52.221775],[-73.614573,-52.144708],[-73.530914,-52.456964],[-73.687856,-52.597833],[-73.397328,-52.636489],[-73.233062,-52.790623],[-73.455963,-52.986505],[-73.198476,-53.104913],[-72.979563,-53.054783],[-72.947377,-52.985772],[-72.953603,-52.893324],[-73.015614,-52.841729],[-72.790842,-52.752699],[-72.673899,-52.65252],[-72.309926,-52.516534],[-72.027731,-52.559261],[-72.398061,-52.783461],[-72.611562,-52.741876],[-72.960357,-52.824965],[-72.92398,-52.886407],[-72.947662,-52.926365],[-72.933746,-53.10475],[-73.171376,-53.256443],[-72.80956,-53.386814],[-72.531728,-53.542087],[-72.503774,-53.313897],[-72.268951,-53.071466],[-72.021962,-53.125421],[-71.906233,-53.010889],[-71.483957,-52.824884],[-71.198582,-52.923904],[-71.360219,-53.116143],[-71.742421,-53.223403],[-72.282297,-53.242771],[-72.453277,-53.407322],[-72.284088,-53.581231],[-71.644643,-53.823663],[-71.285024,-53.886],[-71.03425,-53.809747],[-70.939443,-53.592218],[-70.992747,-53.382989],[-70.809153,-52.961602],[-70.812123,-52.821384],[-69.84658,-52.486543],[-69.672351,-52.530857],[-69.470937,-52.272719],[-69.212256,-52.137953],[-69.485289,-52.132476],[-69.952754,-52.007419],[-71.965241,-51.970625],[-71.981726,-51.844948],[-72.300724,-51.691469],[-72.351212,-51.475978],[-72.258815,-51.245191],[-72.302843,-50.648897],[-72.755787,-50.616444],[-73.177725,-50.749459],[-73.301438,-50.299564],[-73.541475,-50.113736],[-73.57274,-49.932352],[-73.539512,-49.692676],[-73.521115,-49.60896],[-73.542586,-49.491035],[-73.471118,-49.317195],[-73.18434,-49.214256],[-73.009725,-48.990394],[-72.781212,-48.93386],[-72.592334,-48.791129],[-72.57678,-48.452132],[-72.295092,-48.333276],[-72.343047,-48.07045],[-72.543914,-47.9148],[-72.344443,-47.602261],[-72.361186,-47.450953],[-72.038156,-47.287035],[-71.9501,-46.813989],[-71.68717,-46.690069],[-71.770162,-46.112636],[-71.612291,-45.970526],[-71.801788,-45.72403],[-71.713732,-45.53324],[-71.489094,-45.498514],[-71.317167,-45.26721],[-71.588726,-44.978132],[-72.073503,-44.902168],[-71.85455,-44.79096],[-71.497104,-44.742901],[-71.29784,-44.795611],[-71.209783,-44.427571],[-71.822045,-44.40318],[-71.762204,-44.064079],[-71.659885,-43.92631],[-71.761842,-43.828435],[-71.7143,-43.602195],[-71.901731,-43.322006],[-71.742981,-43.190127],[-72.054434,-43.105378],[-72.148537,-42.998718],[-72.148434,-42.592645],[-72.03919,-42.48123],[-72.133706,-42.287599],[-71.736263,-42.08389],[-71.794037,-41.867469],[-71.925915,-41.653012],[-71.853258,-41.567332],[-71.903953,-41.367655],[-71.851449,-40.938327],[-71.955577,-40.720356],[-71.796414,-40.414535],[-71.674044,-40.324101],[-71.823751,-40.210103],[-71.683708,-40.098998],[-71.616632,-39.909863],[-71.714352,-39.601354],[-71.541959,-39.532315],[-71.412045,-39.317961],[-71.430235,-38.999117],[-71.236035,-38.811635],[-70.873835,-38.691436],[-70.848668,-38.527621],[-70.973751,-38.424682],[-71.007418,-38.071008],[-71.18503,-37.706069],[-71.117696,-37.466497],[-71.205597,-37.292658],[-71.089119,-37.103419],[-71.207148,-36.972367],[-71.145343,-36.68825],[-71.043282,-36.484335],[-70.386939,-36.058728],[-70.40823,-35.506204],[-70.542899,-35.209271],[-70.386629,-35.16669],[-70.353711,-34.953266],[-70.227828,-34.58533],[-70.067579,-34.414591],[-70.05758,-34.291187],[-69.828885,-34.23331],[-69.909552,-33.955704],[-69.895367,-33.662285],[-69.787674,-33.379408],[-70.010011,-33.299103],[-70.111194,-33.038447],[-70.000219,-32.876597],[-70.155739,-32.738414],[-70.160829,-32.485303],[-70.321801,-32.280147],[-70.335237,-32.140001],[-70.244467,-31.942235],[-70.42828,-31.870095],[-70.589769,-31.567684],[-70.5414,-31.188173],[-70.339785,-31.041722],[-70.217105,-30.515139],[-69.912136,-30.329517],[-69.835758,-30.161879],[-69.980375,-30.072479],[-69.915599,-29.805621],[-70.040655,-29.297539],[-69.803926,-29.098688],[-69.653031,-28.397852],[-69.420306,-28.212644],[-69.303233,-27.99953],[-69.190191,-27.951368],[-69.01741,-27.460442],[-68.870753,-27.198442],[-68.718617,-27.106665],[-68.330476,-27.044963],[-68.305361,-26.897995],[-68.570151,-26.550626],[-68.575164,-26.30351],[-68.409024,-26.144243],[-68.605963,-25.436999],[-68.516046,-25.183578],[-68.366649,-25.123427],[-68.473051,-24.907936],[-68.555165,-24.862151],[-68.572373,-24.769856],[-68.49553,-24.601805],[-68.451502,-24.629297],[-68.244486,-24.385384],[-67.362369,-24.030367],[-67.013967,-23.000714],[-67.193904,-22.822223],[-67.616772,-22.897258],[-67.77144,-22.888679],[-67.887092,-22.818709],[-67.859187,-22.547305],[-67.951894,-22.334088],[-67.960627,-22.102887],[-68.096226,-21.953956],[-68.198442,-21.57186],[-68.207537,-21.284333],[-68.41631,-20.959805],[-68.555113,-20.913916],[-68.572786,-20.742867],[-68.480957,-20.624735],[-68.685544,-20.516834],[-68.726265,-20.150965],[-68.588341,-20.055571],[-68.561108,-19.844317],[-68.703218,-19.71554],[-68.447626,-19.434627],[-68.663324,-19.273603],[-68.989609,-18.946491],[-68.951445,-18.867323],[-69.033844,-18.649455],[-69.034386,-18.478303],[-69.155438,-18.140235],[-69.334239,-17.805785],[-69.497123,-17.621404],[-69.510089,-17.506588]]],[[[-68.641998,-54.799168],[-68.641882,-54.782971],[-68.627617,-52.639572],[-68.779026,-52.548254],[-69.140248,-52.68377],[-69.417565,-52.451472],[-69.603871,-52.521173],[-69.734351,-52.774459],[-70.001133,-52.841734],[-70.243452,-53.061725],[-70.418993,-53.011716],[-70.473541,-53.309259],[-70.202707,-53.468683],[-69.897822,-53.386644],[-69.352651,-53.355727],[-69.360842,-53.521675],[-69.65144,-53.636231],[-70.17516,-53.760512],[-70.014027,-54.113539],[-69.279612,-54.321547],[-69.881947,-54.312677],[-70.090199,-54.253188],[-70.322499,-54.325291],[-70.843251,-54.263116],[-70.972401,-54.469008],[-71.323069,-54.427667],[-71.563222,-54.510837],[-71.583119,-54.65488],[-70.092844,-54.849054],[-69.730784,-54.803155],[-69.067006,-54.948826],[-68.665842,-54.886407],[-68.641998,-54.799168]]],[[[-67.999257,-55.627537],[-68.345326,-55.344008],[-68.209218,-55.262872],[-68.616078,-55.152276],[-68.441151,-54.939711],[-69.885976,-55.063572],[-70.031077,-55.147638],[-69.788075,-55.305922],[-69.339223,-55.474867],[-69.116607,-55.205662],[-68.897857,-55.327813],[-68.865346,-55.505304],[-68.602528,-55.462335],[-67.999257,-55.627537]]],[[[-67.883168,-55.243829],[-67.270619,-55.306899],[-67.053375,-55.093683],[-67.301829,-54.928888],[-67.941803,-54.90545],[-68.18635,-54.978204],[-68.135081,-55.218845],[-67.883168,-55.243829]]],[[[-70.295155,-55.082452],[-70.706125,-54.968927],[-70.74767,-55.099786],[-70.548085,-55.213556],[-70.295155,-55.082452]]],[[[-69.904164,-54.996759],[-69.776438,-55.034601],[-69.164296,-54.955824],[-69.728342,-54.864516],[-69.904164,-54.996759]]],[[[-71.63093,-54.07879],[-71.542144,-54.269952],[-71.106516,-54.376642],[-70.990142,-54.265802],[-71.179677,-54.085626],[-71.463287,-53.941583],[-71.63093,-54.07879]]],[[[-72.015126,-54.202325],[-71.766103,-54.163995],[-71.652903,-53.926365],[-71.945709,-53.852797],[-72.203196,-53.99627],[-72.015126,-54.202325]]],[[[-70.455036,-53.611598],[-70.71288,-53.70143],[-70.900543,-53.873712],[-70.822743,-54.113539],[-70.540435,-54.221612],[-70.342795,-54.028069],[-70.455036,-53.611598]]],[[[-72.529652,-54.075372],[-72.329905,-54.034601],[-72.348622,-53.831313],[-72.234242,-53.728774],[-72.913238,-53.427016],[-73.584706,-53.582778],[-73.310455,-53.742364],[-73.337758,-53.955255],[-72.850575,-53.955255],[-72.529652,-54.075372]]],[[[-73.837392,-52.70086],[-73.725168,-52.404718],[-74.184368,-52.586801],[-74.123419,-52.706617],[-73.837392,-52.70086]]],[[[-75.126047,-50.494317],[-75.513824,-50.649102],[-75.386464,-50.772068],[-75.126047,-50.494317]]],[[[-74.310414,-50.834161],[-74.181304,-50.782322],[-74.383127,-50.455987],[-74.581207,-50.633559],[-74.310414,-50.834161]]],[[[-75.040639,-50.289483],[-75.157053,-50.021417],[-75.390452,-50.162286],[-75.454945,-50.363946],[-75.22289,-50.436456],[-75.040639,-50.289483]]],[[[-75.198313,-49.771173],[-75.012196,-49.837335],[-74.768422,-50.053318],[-74.474233,-49.944513],[-74.423655,-49.744887],[-74.539418,-49.519301],[-74.44579,-49.302341],[-74.543813,-48.70615],[-74.830312,-48.689548],[-75.051503,-48.857029],[-74.85912,-49.110772],[-75.037221,-49.260431],[-75.461985,-49.306573],[-75.325266,-49.459649],[-75.198313,-49.771173]]],[[[-75.328359,-48.552179],[-75.34435,-48.427423],[-75.655751,-48.48504],[-75.541656,-48.70086],[-75.328359,-48.552179]]],[[[-74.499135,-48.583185],[-74.728586,-48.20672],[-74.996246,-48.603692],[-74.60733,-48.693943],[-74.499135,-48.583185]]],[[[-75.160756,-48.298435],[-75.031117,-48.44378],[-74.841298,-48.359308],[-74.804514,-48.174493],[-75.017505,-48.08302],[-75.256337,-48.068617],[-75.160756,-48.298435]]],[[[-75.149892,-48.65838],[-75.098704,-48.465916],[-75.34911,-48.059177],[-75.585317,-48.085707],[-75.554189,-48.397149],[-75.317942,-48.348891],[-75.282826,-48.630548],[-75.149892,-48.65838]]],[[[-75.270619,-48.027765],[-74.727379,-48.105892],[-74.788324,-47.812324],[-75.167773,-47.893604],[-75.270619,-48.027765]]],[[[-74.752919,-45.80755],[-74.883534,-45.929376],[-75.108266,-45.8742],[-75.07433,-46.093845],[-74.780751,-46.011489],[-74.752919,-45.80755]]],[[[-74.502838,-45.732354],[-74.241811,-45.675958],[-74.273549,-45.495294],[-74.421254,-45.454278],[-74.502838,-45.732354]]],[[[-73.666168,-45.436944],[-73.818267,-45.642511],[-73.629872,-45.737563],[-73.584218,-45.512628],[-73.666168,-45.436944]]],[[[-73.731923,-45.214776],[-73.866078,-44.994561],[-74.173899,-45.026056],[-73.989573,-45.245782],[-73.731923,-45.214776]]],[[[-73.926829,-44.628839],[-74.400543,-44.626072],[-74.258697,-44.804457],[-73.926829,-44.628839]]],[[[-73.382476,-44.587823],[-73.407582,-44.822442],[-73.14745,-44.911879],[-72.837636,-44.710138],[-72.721181,-44.528009],[-73.002024,-44.361261],[-73.246246,-44.437188],[-73.382476,-44.587823]]],[[[-74.334625,-43.281671],[-73.847491,-43.423483],[-73.669014,-43.363847],[-73.721425,-43.141697],[-73.490061,-43.10003],[-73.577382,-42.965753],[-73.491933,-42.818617],[-73.809153,-42.608657],[-73.666168,-42.354099],[-73.396108,-42.309015],[-73.456451,-42.044366],[-73.690989,-41.809015],[-73.866038,-41.892267],[-74.006174,-41.845147],[-74.053336,-42.130345],[-74.159503,-42.241298],[-74.167363,-42.882514],[-74.407216,-43.237888],[-74.334625,-43.281671]]]]} | B4: Chile
A5: {"type":"Polygon","coordinates":[[[-69.510089,-17.506588],[-69.497123,-17.621404],[-69.334239,-17.805785],[-69.155438,-18.140235],[-69.034386,-18.478303],[-69.033844,-18.649455],[-68.951445,-18.867323],[-68.989609,-18.946491],[-68.663324,-19.273603],[-68.447626,-19.434627],[-68.703218,-19.71554],[-68.561108,-19.844317],[-68.588341,-20.055571],[-68.726265,-20.150965],[-68.685544,-20.516834],[-68.480957,-20.624735],[-68.572786,-20.742867],[-68.555113,-20.913916],[-68.41631,-20.959805],[-68.207537,-21.284333],[-68.198442,-21.57186],[-68.096226,-21.953956],[-67.960627,-22.102887],[-67.951894,-22.334088],[-67.859187,-22.547305],[-67.887092,-22.818709],[-67.77144,-22.888679],[-67.547113,-22.892503],[-67.193904,-22.822223],[-67.026628,-22.639392],[-67.032725,-22.524567],[-66.785092,-22.427622],[-66.735896,-22.225051],[-66.307602,-22.077049],[-66.222465,-21.786938],[-66.094488,-21.83293],[-65.744613,-22.11405],[-65.579894,-22.086454],[-65.020368,-22.096583],[-64.596207,-22.20655],[-64.572023,-22.343183],[-64.428285,-22.542344],[-64.355731,-22.751943],[-64.160549,-22.438474],[-63.933173,-22.001808],[-63.813129,-22.003049],[-62.818564,-22.000878],[-62.783476,-22.130896],[-62.650357,-22.234456],[-62.275703,-21.066568],[-62.26883,-20.553111],[-61.94425,-20.104146],[-61.753203,-19.64588],[-60.006384,-19.298097],[-59.089541,-19.286729],[-58.175282,-19.821373],[-58.141847,-20.000897],[-58.158797,-20.165125],[-57.859745,-19.980123],[-58.124639,-19.729906],[-57.789,-19.059249],[-57.782334,-18.910421],[-57.56674,-18.256094],[-57.551082,-18.183643],[-57.730089,-17.846093],[-57.800731,-17.533451],[-58.010175,-17.49676],[-58.399144,-17.237448],[-58.480276,-16.683683],[-58.342661,-16.473154],[-58.464721,-16.33125],[-60.16069,-16.264794],[-60.246395,-15.478279],[-60.582241,-15.098871],[-60.269805,-15.083368],[-60.291716,-14.630062],[-60.473513,-14.117225],[-60.387188,-13.98328],[-60.472635,-13.797865],[-60.896743,-13.552918],[-61.347724,-13.493697],[-61.83635,-13.540619],[-62.109408,-13.248958],[-62.114679,-13.150204],[-62.424118,-13.126536],[-62.472125,-13.068452],[-62.789832,-13.000652],[-62.988011,-12.843866],[-63.075034,-12.652663],[-63.317913,-12.701963],[-63.657738,-12.475413],[-63.862893,-12.469212],[-63.921236,-12.544349],[-64.395729,-12.457326],[-64.489392,-12.239459],[-64.739532,-12.144581],[-64.7925,-12.032546],[-64.998121,-11.908936],[-65.065559,-11.75308],[-65.196197,-11.741814],[-65.222655,-11.517435],[-65.319548,-11.476404],[-65.394738,-11.153427],[-65.299601,-10.969665],[-65.404737,-10.799236],[-65.410938,-10.44918],[-65.284822,-10.206818],[-65.336834,-9.967246],[-65.29911,-9.841259],[-65.416235,-9.680132],[-65.510777,-9.734082],[-65.583977,-9.837228],[-65.834065,-9.758266],[-66.086995,-9.784518],[-66.660087,-9.945335],[-66.902656,-10.09313],[-67.184706,-10.326707],[-67.323509,-10.318852],[-67.58463,-10.501787],[-67.721727,-10.705495],[-67.862649,-10.65878],[-68.112091,-10.714074],[-68.29332,-10.978967],[-68.775926,-11.140611],[-68.884034,-11.016381],[-69.39594,-10.935042],[-69.577635,-10.952302],[-68.684252,-12.502492],[-68.980953,-12.867947],[-68.970747,-13.501449],[-69.023844,-13.634981],[-68.982968,-13.972221],[-68.864448,-14.191226],[-69.01015,-14.245899],[-68.990254,-14.379018],[-69.234658,-14.574251],[-69.267628,-14.750675],[-69.370541,-14.801524],[-69.384313,-14.981772],[-69.1481,-15.233333],[-69.291166,-15.350845],[-69.430021,-15.62628],[-69.184868,-16.195031],[-68.982038,-16.210017],[-68.833494,-16.328976],[-69.027875,-16.454137],[-69.037073,-16.670247],[-69.182362,-16.728745],[-69.413588,-17.022267],[-69.6228,-17.185565],[-69.510089,-17.506588]]]} | B5: Bolivia
